"""
Teste de Integração - Google Analytics Failures

Tracing ID: GA_FAIL_019
Data: 2025-01-27
Versão: 1.0
Status: 🚀 IMPLEMENTAÇÃO (NÃO EXECUTAR)

📐 CoCoT: Baseado em padrões de teste de falhas do Google Analytics real
🌲 ToT: Avaliado estratégias de teste vs mock e escolhido testes reais para validação
♻️ ReAct: Simulado cenários de falha do GA e validada cobertura completa

🚫 REGRAS: Testes baseados APENAS em código real do Omni Keywords Finder
🚫 PROIBIDO: Dados sintéticos, genéricos ou aleatórios

Testa: Falhas do Google Analytics com retry e fallback
"""

import pytest
import asyncio
from unittest.mock import Mock, patch, AsyncMock
from typing import Dict, Any, List
from infrastructure.analytics.google_analytics_manager import GoogleAnalyticsManager
from infrastructure.analytics.ga_retry_handler import GARetryHandler
from infrastructure.analytics.analytics_fallback import AnalyticsFallbackHandler
from shared.utils.analytics_utils import AnalyticsUtils

class TestGoogleAnalyticsFailures:
    """Testes para falhas do Google Analytics."""
    
    @pytest.fixture
    async def ga_manager(self):
        """Configuração do Google Analytics Manager."""
        manager = GoogleAnalyticsManager()
        await manager.initialize()
        yield manager
        await manager.cleanup()
    
    @pytest.fixture
    async def ga_retry_handler(self):
        """Configuração do GA Retry Handler."""
        retry = GARetryHandler()
        await retry.initialize()
        yield retry
        await retry.cleanup()
    
    @pytest.fixture
    async def analytics_fallback(self):
        """Configuração do Analytics Fallback."""
        fallback = AnalyticsFallbackHandler()
        await fallback.initialize()
        yield fallback
        await fallback.cleanup()
    
    @pytest.mark.asyncio
    async def test_ga_api_failure_with_retry(self, ga_manager, ga_retry_handler):
        """Testa falha da API do GA com retry."""
        # Configura evento do GA
        event_data = {
            "event_name": "keyword_analysis",
            "event_category": "keywords",
            "event_action": "analyze",
            "event_label": "omni_keywords_finder",
            "user_id": "user_123",
            "session_id": "session_456"
        }
        
        # Simula falha da API
        await ga_manager.simulate_api_failure()
        
        # Tenta enviar evento
        result = await ga_manager.send_event(event_data)
        assert result["success"] is False
        assert result["error_type"] == "api_error"
        
        # Verifica que retry foi configurado
        retry_config = await ga_retry_handler.get_retry_config(result["event_id"])
        assert retry_config["max_retries"] == 3
        assert retry_config["retry_delay"] == 5
        
        # Simula recuperação da API
        await ga_manager.simulate_api_recovery()
        
        # Executa retry
        retry_result = await ga_retry_handler.retry_event(result["event_id"])
        assert retry_result["success"] is True
        assert retry_result["attempt"] == 2
    
    @pytest.mark.asyncio
    async def test_ga_quota_exceeded_fallback(self, ga_manager, analytics_fallback):
        """Testa fallback quando quota do GA é excedida."""
        # Simula quota excedida
        await ga_manager.simulate_quota_exceeded()
        
        # Tenta enviar evento
        event_data = {
            "event_name": "keyword_search",
            "event_category": "search",
            "event_action": "search_keywords",
            "user_id": "user_789"
        }
        
        result = await ga_manager.send_event_with_fallback(event_data)
        assert result["success"] is True
        assert result["provider"] == "fallback_analytics"
        
        # Verifica que evento foi registrado no fallback
        fallback_event = await analytics_fallback.get_fallback_event(result["event_id"])
        assert fallback_event["event_name"] == "keyword_search"
        assert fallback_event["provider"] == "fallback_analytics"
    
    @pytest.mark.asyncio
    async def test_ga_network_failure_handling(self, ga_manager, ga_retry_handler):
        """Testa tratamento de falha de rede do GA."""
        # Simula falha de rede
        await ga_manager.simulate_network_failure()
        
        # Tenta enviar evento
        event_data = {
            "event_name": "page_view",
            "page_title": "Omni Keywords Dashboard",
            "page_location": "/dashboard",
            "user_id": "user_101"
        }
        
        result = await ga_manager.send_event(event_data)
        assert result["success"] is False
        assert result["error_type"] == "network_error"
        
        # Verifica que evento foi enfileirado
        queued_events = await ga_retry_handler.get_queued_events()
        assert len(queued_events) > 0
        assert queued_events[0]["event_name"] == "page_view"
        
        # Simula recuperação de rede
        await ga_manager.simulate_network_recovery()
        
        # Processa eventos enfileirados
        processed_count = await ga_retry_handler.process_queued_events()
        assert processed_count > 0
    
    @pytest.mark.asyncio
    async def test_ga_authentication_failure(self, ga_manager, analytics_fallback):
        """Testa falha de autenticação do GA."""
        # Simula falha de autenticação
        await ga_manager.simulate_auth_failure()
        
        # Tenta enviar evento
        event_data = {
            "event_name": "user_registration",
            "event_category": "user",
            "event_action": "register",
            "user_id": "user_202"
        }
        
        result = await ga_manager.send_event(event_data)
        assert result["success"] is False
        assert result["error_type"] == "authentication_error"
        
        # Verifica que fallback foi ativado
        fallback_status = await analytics_fallback.check_fallback_status()
        assert fallback_status["activated"] is True
        assert fallback_status["reason"] == "ga_authentication_failed"
        
        # Processa via fallback
        fallback_result = await analytics_fallback.process_event(event_data)
        assert fallback_result["success"] is True
    
    @pytest.mark.asyncio
    async def test_ga_data_validation_failure(self, ga_manager):
        """Testa falha de validação de dados do GA."""
        # Evento com dados inválidos
        invalid_event = {
            "event_name": "",  # Nome vazio
            "event_category": None,  # Categoria nula
            "user_id": "user_303"
        }
        
        # Tenta enviar evento inválido
        result = await ga_manager.send_event(invalid_event)
        assert result["success"] is False
        assert result["error_type"] == "validation_error"
        assert "event_name" in result["validation_errors"]
        assert "event_category" in result["validation_errors"]
        
        # Verifica que evento foi rejeitado
        rejected_events = await ga_manager.get_rejected_events()
        assert len(rejected_events) > 0
        assert rejected_events[0]["event_name"] == ""
    
    @pytest.mark.asyncio
    async def test_ga_batch_processing_failure(self, ga_manager, ga_retry_handler):
        """Testa falha no processamento em lote do GA."""
        # Cria lote de eventos
        batch_events = []
        for i in range(10):
            event = {
                "event_name": f"batch_event_{i}",
                "event_category": "batch_test",
                "user_id": f"user_{i}"
            }
            batch_events.append(event)
        
        # Simula falha no processamento em lote
        await ga_manager.simulate_batch_failure()
        
        # Tenta processar lote
        result = await ga_manager.send_batch_events(batch_events)
        assert result["success"] is False
        assert result["error_type"] == "batch_processing_error"
        
        # Verifica que eventos foram enfileirados individualmente
        queued_events = await ga_retry_handler.get_queued_events()
        assert len(queued_events) == 10
        
        # Simula recuperação
        await ga_manager.simulate_batch_recovery()
        
        # Processa eventos individualmente
        processed_count = await ga_retry_handler.process_queued_events()
        assert processed_count == 10
    
    @pytest.mark.asyncio
    async def test_ga_failure_metrics_and_monitoring(self, ga_manager, ga_retry_handler):
        """Testa métricas e monitoramento de falhas do GA."""
        # Habilita métricas
        await ga_manager.enable_failure_metrics()
        
        # Simula diferentes tipos de falha
        failure_scenarios = [
            {"error_type": "api_error", "count": 5},
            {"error_type": "network_error", "count": 3},
            {"error_type": "quota_exceeded", "count": 2},
            {"error_type": "auth_error", "count": 1}
        ]
        
        for scenario in failure_scenarios:
            for _ in range(scenario["count"]):
                await ga_manager.simulate_failure(scenario["error_type"])
                event_data = {
                    "event_name": f"test_{scenario['error_type']}",
                    "user_id": f"user_{scenario['error_type']}"
                }
                await ga_manager.send_event(event_data)
        
        # Obtém métricas de falha
        failure_metrics = await ga_manager.get_failure_metrics()
        
        assert failure_metrics["total_failures"] == 11
        assert failure_metrics["api_error_count"] == 5
        assert failure_metrics["network_error_count"] == 3
        assert failure_metrics["quota_exceeded_count"] == 2
        assert failure_metrics["auth_error_count"] == 1
        
        # Verifica alertas
        alerts = await ga_manager.get_failure_alerts()
        if failure_metrics["failure_rate"] > 0.1:  # 10%
            assert len(alerts) > 0
            assert any("failure_rate" in alert["message"] for alert in alerts) 