============================= test session starts =============================
platform win32 -- Python 3.11.0, pytest-8.1.1, pluggy-1.5.0
rootdir: D:\PROJETOS\SISTEMAS\omni_keywords_finder
configfile: pytest.ini
plugins: anyio-4.9.0, Faker-24.14.1, asyncio-0.26.0, cov-4.1.0
asyncio: mode=Mode.STRICT, asyncio_default_fixture_loop_scope=None, asyncio_default_test_loop_scope=function
collected 0 items / 1 error

=================================== ERRORS ====================================
___________ ERROR collecting tests/integration/api/test_keywords.py ___________
ImportError while importing test module 'D:\PROJETOS\SISTEMAS\omni_keywords_finder\tests\integration\api\test_keywords.py'.
Hint: make sure your test modules/packages have valid Python names.
Traceback:
C:\Program Files\Python311\Lib\importlib\__init__.py:126: in import_module
    return _bootstrap._gcd_import(name[level:], package, level)
tests\integration\api\test_keywords.py:5: in <module>
    from app.main import create_app
E   ModuleNotFoundError: No module named 'app.main'
============================== warnings summary ===============================
C:\Users\SEDUC\Desktop\PROJETOS\omni_keywords_finder\.venv\Lib\site-packages\_pytest\config\__init__.py:1439
  C:\Users\SEDUC\Desktop\PROJETOS\omni_keywords_finder\.venv\Lib\site-packages\_pytest\config\__init__.py:1439: PytestConfigWarning: Unknown config option: timeout
  
    self._warn_or_fail_if_strict(f"Unknown config option: {key}\n")

-- Docs: https://docs.pytest.org/en/stable/how-to/capture-warnings.html
=========================== short test summary info ===========================
ERROR tests/integration/api/test_keywords.py
!!!!!!!!!!!!!!!!!!! Interrupted: 1 error during collection !!!!!!!!!!!!!!!!!!!!
========================= 1 warning, 1 error in 0.85s =========================
